Workbook

Sheet ЗАДАНИЕ1
A1: Фамилия И.О. | B1: Отдел | C1: Коэфф. надбавки | D1: Оклад, у.е. | E1: Надбавка, у.е. | F1: Налог, у.е. | G1: Столбец1
A2: Ангелочкин А.А | B2: ТКБ | C2: 1.2 | D2: 750 | E2: =ЗАДАНИЕ1!$D2*ЗАДАНИЕ1!$C2 -> 900
A3: Ангелочкина А.А | B3: АПС | C3: 1 | D3: 600 | E3: =ЗАДАНИЕ1!$D3*ЗАДАНИЕ1!$C3 -> 600
A4: Везунчиков В.В | B4: ОТД | C4: 1.5 | D4: 800 | E4: =ЗАДАНИЕ1!$D4*ЗАДАНИЕ1!$C4 -> 1200
A5: Везунчикова В.В | B5: ОТД | C5: 1.2 | D5: 1130 | E5: =ЗАДАНИЕ1!$D5*ЗАДАНИЕ1!$C5 -> 1356
A6: Веселая В.В | B6: ОНК | C6: 1 | D6: 1000 | E6: =ЗАДАНИЕ1!$D6*ЗАДАНИЕ1!$C6 -> 1000
A7: Веселый В.В | B7: ОНК | C7: 1.2 | D7: 1350 | E7: =ЗАДАНИЕ1!$D7*ЗАДАНИЕ1!$C7 -> 1620
A8: Добрейший Д.Д | B8: ТКБ | C8: 1 | D8: 1100 | E8: =ЗАДАНИЕ1!$D8*ЗАДАНИЕ1!$C8 -> 1100
A9: Добрецов Д.Д | B9: АПС | C9: 1.2 | D9: 1520 | E9: =ЗАДАНИЕ1!$D9*ЗАДАНИЕ1!$C9 -> 1824
A10: Добрецова Д.Д | B10: ОТД | C10: 1.2 | D10: 1520 | E10: =ЗАДАНИЕ1!$D10*ЗАДАНИЕ1!$C10 -> 1824
A11: Душечкин Д.Д | B11: ТКБ | C11: 1 | D11: 1090 | E11: =ЗАДАНИЕ1!$D11*ЗАДАНИЕ1!$C11 -> 1090
A12: Душечкин Д.Д | B12: ТКБ | C12: 1 | D12: 1180 | E12: =ЗАДАНИЕ1!$D12*ЗАДАНИЕ1!$C12 -> 1180
A13: Душечкина Д.Д | B13: ОТД | C13: 1.4 | D13: 1460 | E13: =ЗАДАНИЕ1!$D13*ЗАДАНИЕ1!$C13 -> 2044
... A50: Ясная Я.Я | B50: ОНК | C50: 1 | D50: 1020 | E50: =ЗАДАНИЕ1!$D50*ЗАДАНИЕ1!$C50 -> 1020
E51: =ЗАДАНИЕ1!$D51*ЗАДАНИЕ1!$C51 -> 0

Sheet ЗАДАНИЕ2
A1: ID заказа | B1: Наименование | C1: Торговая марка | D1: Цена, р. | E1: Кол-во, шт | F1: Скидка, р.
A2: K001 | B2: Кроссовки | C2: Adidas | D2: 5150 | E2: 15 | F2: 0
A3: K002 | B3: Кроссовки | C3: Puma | D3: 3520 | E3: 30 | F3: 400
A4: K003 | B4: Кроссовки | C4: Skechers | D4: 2860 | E4: 24 | F4: 500
A5: K004 | B5: Кроссовки | C5: Brooks | D5: 2990 | E5: 15 | F5: 500
A6: K005 | B6: Спортивный костюм | C6: Nike | D6: 4500 | E6: 8 | F6: 300
A7: K006 | B7: Жилет | C7: Adidas | D7: 1890 | E7: 9 | F7: 0
A8: K007 | B8: Майка | C8: Puma | D8: 1230 | E8: 28 | F8: 400
A9: K008 | B9: Майка | C9: Reebok | D9: 1175 | E9: 25 | F9: 500
A10: K009 | B10: Спортивный костюм | C10: Adidas | D10: 3485 | E10: 35 | F10: 0
A11: K010 | B11: Шорты | C11: Asics | D11: 1350 | E11: 10 | F11: 10
A12: K011 | B12: Джемпер | C12: Puma | D12: 2000 | E12: 4 | F12: 400
A13: K012 | B13: Фуфайка | C13: Termit | D13: 1570 | E13: 10 | F13: 300
... A15: K014 | B15: Брюки | C15: Reebok | D15: 2450 | E15: 26 | F15: 500

Sheet ЗАДАНИЕ3
A1: Фамилия | B1: Имя | C1: Отчество | D1: пол | E1: дата рождения | F1: Город | G1: отдел | H1: оклад, € | I1: Номер страховки
A2: Ангелочкин | B2: Антон | C2: Алексеевич | D2: м | E2: 28010 | F2: Москва | G2: ТКБ | H2: 1510
A3: Ангелочкина | B3: Анна | C3: Алексеевна | D3: ж | E3: 28994 | F3: Звенигород | G3: АПС | H3: 5440 | I3: А454МР
A4: Везунчиков | B4: Виктор | C4: Васильевич | D4: м | E4: 26452 | F4: Москва | G4: ОТД | H4: 2050
A5: Везунчикова | B5: Вера | C5: Васильевна | D5: ж | E5: 26504 | F5: Нижний Новгород | G5: ОТД | H5: 1800
A6: Веселая | B6: Валентина | C6: Викторовна | D6: ж | E6: 28493 | F6: Екатеринбург | G6: ОНК | H6: 5750 | I6: В858ОР
A7: Веселый | B7: Василий | C7: Викторович | D7: м | E7: 26065 | F7: Нижний Новгород | G7: ОНК | H7: 4000
A8: Добрейший | B8: Даниил | C8: Дмитриевич | D8: м | E8: 25013 | F8: Москва | G8: ТКБ | H8: 3600
A9: Добрецов | B9: Денис | C9: Давидович | D9: м | E9: 24714 | F9: Нижний Новгород | G9: АПС | H9: 7360 | I9: К909ОМ
A10: Добрецова | B10: Дарья | C10: Дмитриевна | D10: ж | E10: 31225 | F10: Казань | G10: ОТД | H10: 1800
A11: Душечкин | B11: Дмитрий | C11: Данилович | D11: м | E11: 24630 | F11: Звенигород | G11: ТКБ | H11: 3000 | I11: А222СР
A12: Душечкин | B12: Даниил | C12: Дмитриевич | D12: м | E12: 23440 | F12: Казань | G12: ТКБ | H12: 3450
A13: Душечкина | B13: Дина | C13: Дмитриевна | D13: ж | E13: 18084 | F13: Москва | G13: ОТД | H13: 2700
A14: Замечательная | B14: Зинаида | C14: Захаровна | D14: ж | E14: 25538 | F14: Казань | G14: ОНК | H14: 8500 | I14: М555ММ
A15: Замечательный | B15: Захар | C15: Захарович | D15: м | E15: 21318 | F15: Ярославль | G15: ТКБ | H15: 4650
A16: Красавцев | B16: Константин | C16: Кириллович | D16: м | E16: 23370 | F16: Нижний Новгород | G16: ОТД | H16: 2070 | I16: Т333УТ
A17: Любовь | B17: Леонид | C17: Леонидович | D17: м | E17: 27133 | F17: Нижний Новгород | G17: АПС | H17: 6400
A18: Любовь | B18: Лариса | C18: Леонтьевна | D18: ж | E18: 28320 | F18: Москва | G18: ТКБ | H18: 2400
A19: Мирная | B19: Марина | C19: Максимовна | D19: ж | E19: 24957 | F19: Москва | G19: ОТД | H19: 3100 | I19: Т656АМ
A20: Мирный | B20: Максим | C20: Михайлович | D20: м | E20: 23048 | F20: Санкт-Петербург | G20: ТКБ | H20: 3480
A21: Неунывающая | B21: Нина | C21: Николаевна | D21: ж | E21: 21450 | F21: Звенигород | G21: ОТД | H21: 900
A22: Неунывающий | B22: Никита | C22: Николаевич | D22: м | E22: 25494 | F22: Владимир | G22: ОТД | H22: 905
A23: Оптимистов | B23: Олег | C23: Осипович | D23: м | E23: 23091 | F23: Москва | G23: ОНК | H23: 5750 | I23: С001ОС
A24: Оптимистова | B24: Ольга | C24: Олеговна | D24: ж | E24: 32763 | F24: Владимир | G24: ОТД | H24: 1800
A25: Отличницева | B25: Оксана | C25: Олеговна | D25: ж | E25: 30253 | F25: Москва | G25: ТКБ | H25: 3000
A26: Позитивная | B26: Полина | C26: Платоновна | D26: ж | E26: 32451 | F26: Красногорск | G26: ОНК | H26: 4750 | I26: К757ОТ
A27: Позитивов | B27: Платон | C27: Петрович | D27: м | E27: 24172 | F27: Красногорск | G27: ОТД | H27: 1800
A28: Праздников | B28: Павел | C28: Платонович | D28: м | E28: 28244 | F28: Москва | G28: АПС | H28: 10880
A29: Праздникова | B29: Полина | C29: Павловна | D29: ж | E29: 21929 | F29: Санкт-Петербург | G29: ОНК | H29: 5000 | I29: М303РУ
A30: Прекрасная | B30: Пелагея | C30: Платоновна | D30: ж | E30: 22196 | F30: Санкт-Петербург | G30: ОТД | H30: 1900
A31: Прекрасный | B31: Петр | C31: Павлович | D31: м | E31: 31967 | F31: Красногорск | G31: ТКБ | H31: 3450
A32: Приятный | B32: Павел | C32: Петрович | D32: м | E32: 22803 | F32: Москва | G32: ТКБ | H32: 2550 | I32: М007НУ
A33: Приятный | B33: Платон | C33: Петрович | D33: м | E33: 32940 | F33: Красногорск | G33: АПС | H33: 7360
A34: Радостная | B34: Раиса | C34: Романовна | D34: ж | E34: 30735 | F34: Санкт-Петербург | G34: АПС | H34: 3600
A35: Радостная | B35: Рената | C35: Руслановна | D35: ж | E35: 27437 | F35: Звенигород | G35: ОНК | H35: 8500 | I35: О777ОО
A36: Радостнов | B36: Руслан | C36: Романович | D36: м | E36: 30483 | F36: Санкт-Петербург | G36: ТКБ | H36: 3400
A37: Радостный | B37: Роман | C37: Русланович | D37: м | E37: 22608 | F37: Москва | G37: ОТД | H37: 2070
A38: Романтичный | B38: Роман | C38: Русланович | D38: м | E38: 25887 | F38: Ярославль | G38: ТКБ | H38: 4650 | I38: А555АА
A39: Счастливцев | B39: Сергей | C39: Семенович | D39: м | E39: 22127 | F39: Ярославль | G39: ОНК | H39: 2515
A40: Счастливцев | B40: Станислав | C40: Семенович | D40: м | E40: 23927 | F40: Красногорск | G40: ТКБ | H40: 3450
...
